<!-- Author + Copyright (C) Aravind Rajeswaran, rajeswaran.aravind@gmail.com. 
See LICENSE file for legal notices. LICENSE must be kept together with this file. -->
<mujoco model="PointMass">
    <compiler inertiafromgeom="true" angle="radian" />
    <default>
        <joint armature="0.01" damping="0.1" limited="true"/>
        <geom contype="0" friction="1 0.1 0.1" rgba="0.7 0.7 0 1"/>
        <motor ctrllimited="true" ctrlrange="-1.0 1.0" />
    </default>
    <option gravity="0 0 0" integrator="RK4" timestep="0.01"/>

    <asset>
        <texture type="skybox" builtin="gradient" rgb1=".1 .12 .15" rgb2="0 0 0" width="100" height="100"/>
        <texture builtin="flat" height="100" name="grayplane" rgb1="0.4 0.4 0.4" rgb2=".1 0.15 0.2" type="2d" width="100"/>
        <material name="grayfloor" reflectance="0" shininess="0" specular="1" texture="grayplane"/>
    </asset>

    <worldbody>
        <!-- Arena -->
        <geom conaffinity="0" contype="0" name="ground" pos="0 0 0" rgba="0.9 0.9 0.9 1" size="1.5 1.5 .05" type="plane" material="grayfloor"/>
        <geom conaffinity="0" fromto="-1.5 -1.5 .02 1.5 -1.5 .02" name="sideS" rgba="0.3 0.4 0.3 1.0" size=".04" type="capsule" mass="0.1"/>
        <geom conaffinity="0" fromto=" 1.5 -1.5 .02 1.5  1.5 .02" name="sideE" rgba="0.3 0.4 0.3 1.0" size=".04" type="capsule" mass="0.1"/>
        <geom conaffinity="0" fromto="-1.5  1.5 .02 1.5  1.5 .02" name="sideN" rgba="0.3 0.4 0.3 1.0" size=".04" type="capsule" mass="0.1"/>
        <geom conaffinity="0" fromto="-1.5 -1.5 .02 -1.5 1.5 .02" name="sideW" rgba="0.3 0.4 0.3 1.0" size=".04" type="capsule" mass="0.1"/>

        <!-- Agent -->
        <body name="agent" pos="0 0 .05">
            <joint axis="1 0 0" name="agent_x" pos="0 0 0" range="-1.4 1.4" stiffness="0" type="slide"/>
            <joint axis="0 1 0" name="agent_y" pos="0 0 0" range="-1.4 1.4" stiffness="0" type="slide"/>
            <geom conaffinity="1" contype="1" name="agent" pos="0 0 0" rgba="0.2 0.2 0.6 1" size=".05" type="sphere"/>
        </body>

        <!-- Target -->
        <site name="target" pos="1.0 0 .05" rgba="0.6 0.2 0.2 0.2" size=".07" type="sphere" />

    </worldbody>

    <actuator>
        <motor gear="10.0" joint="agent_x"/>
        <motor gear="10.0" joint="agent_y"/>
    </actuator>

</mujoco>
