<mujoco model="walker_generic">
   <include file="../../misc/skybox.xml" />
   <include file="../../misc/visual.xml" />
   <include file="../../misc/materials.xml" />
   <compiler angle="degree" coordinate="global" inertiafromgeom="true" />
   <default>
      <joint armature="0.01" damping=".1" limited="true" />
      <geom conaffinity="0" condim="3" contype="1" density="1000" friction=".7 .1 .1" material="self" />
   </default>
   <option integrator="RK4" timestep="0.002" />
      <actuator>
         <motor ctrllimited="true" ctrlrange="-1.0 1.0" gear="100" joint="left1_joint" />
      </actuator>
      <worldbody>
         <light cutoff="100" diffuse="1 1 1" dir="-1 -0 -1.5" directional="true" exponent="1" pos="0 0 1.3" specular=".1 .1 .1" />
         <geom conaffinity="1" condim="3" material="grid" name="floor" pos="0 0 0" size="40 40 40" type="plane" />
         <body name="torso" pos="0 0 1.6">
            <camera mode="trackcom" name="tilted" pos="2.7 3 1" xyaxes="1 -.9 0 0 0 -1" />
            <camera mode="trackcom" name="track" pos="0 3 1" xyaxes="1 0 0 0 0 -1" />
            <joint armature="0" axis="1 0 0" damping="0" limited="false" name="rootx" pos="0 0 0" stiffness="0" type="slide" />
            <joint armature="0" axis="0 0 1" damping="0" limited="false" name="rootz" pos="0 0 0" ref="1.25" stiffness="0" type="slide" />
            <joint armature="0" axis="0 1 0" damping="0" limited="false" name="rooty" pos="0 0 1.25" stiffness="0" type="hinge" />
            <geom friction="0.9" fromto="0 0 1.6 0 0 1.0" name="torso_geom" size="0.07" type="capsule" />
            <body name="left1" pos="0 0 1.0">
               <geom friction="0.9" fromto="0 0 1.0 0 0 0.52" name="left1_geom" size="0.05600000000000001" type="capsule" />
               <joint axis="0 -1 0" name="left1_joint" pos="0 0 1.0" range="-75 75" type="hinge" />
         </body>
         </body>
      </worldbody>
</mujoco>